Workbook

Sheet Post-conf leads (Round 2)
A1: First Name | B1: Last Name | C1: Email Address | D1: Company Name | E1: Title | F1: Mobile Phone Number | G1: Device used to scan badge | H1: Contact Owner | I1: Email Sent (Y/N) Date? | J1: LinkedIn Sent/Connected (Y/N) Date? | K1: Called (Y/N) Date? | L1: Lead Score | M1: Role of this person | N1: DURING-Summit notes | O1: DURING-summit follow-up notes | P1: POST-Summit Follow-up Notes | Q1: POST-Summit Follow-up Jira tickets | R1: POST-Summit lead qual & follow-up planning done | S1: POST-Summit follow-ups done (week of Oct 21-25) | T1: ZoomInfo follow-up Jan 2025 | U1: Call target, Jan 2025 | V1: Called Jan 2025 | W1: Sent LinkedIN Invite 2025Apr | X1: Created date/time US/Eastern | Y1: Qualified | Z1: Is the person currently evaluating solutions related to [specific problem/industry]? | AA1: What is the timeframe for choosing a solution? | AB1: Is there a budget for this business need? | AC1: Work Phone Number | AD1: Work City | AE1: Work State | AF1: Lead Transcription Status | AG1: Lead Source | AH1: Last Update US/Eastern | AI1: What State do you reside in: | AJ1: Country you reside in: | AK1: Sponsorship Level | AL1: Event Sponsor
A2: Catherine Toth | C2: cathy.toth@acatoim.com | D2: Acato Information Management LLC | H2: Hari | L2: 1 | N2: Collected contact info after last day SAFe gov session | T2: TRUE | U2: FALSE | V2: FALSE | W2: FALSE
A3: Bill Toth | C3: bill.toth@acatoim.com | D3: Acato Information Management LLC | H3: Hari | L3: 1 | N3: Collected contact info after last day SAFe gov session | T3: TRUE | U3: FALSE | V3: FALSE
A4: Alexander Miner | C4: alexander.r.miner@frb.gov | D4: agile coach | H4: Hari | L4: 1 | N4: Collected contact info after last day SAFe gov session | T4: TRUE | U4: FALSE | V4: FALSE
A5: Bhavani | B5: Krishnan | C5: bhavani.krishnan@agilevelocity.com | D5: Agile Velocity | E5: Enterprise Agile Coach | F5: 571.246.0602 | G5: iPad Mini (LSA/Keith) / Kurt's iPhone (personal) | H5: Kurt | L5: 4 | M5: Budget authority | N5: Looking for partnership opportunity. Spoke to Kurt. They are in the commercial space and interact with cyber security. They are very interested in looking at their women owned an 8a. Spoke with her and their chief revenue officer James Hawks. | O5: Other: X | P5: EMAIL_PARTNER_HIGH: Send email asking for follow-up discussion. Setup further discussion on how we can partner and help one another by leveraging their 8a. Meeting scheduled for 10/24/2024 to explore strategic plan and partnering with her and James Hawks | R5: TRUE | S5: TRUE | T5: TRUE | U5: FALSE | V5: FALSE | X5: =DATE(2024,10,15)+TIME(10,49,18) -> 45580.451 | Y5: Yes | AG5: Scanned | AH5: =DATE(2024,10,15)+TIME(11,2,31) -> 45580.46 | AI5: Virginia | AJ5: United States | AK5: Large Solution | AL5: Yes
A6: Erin | B6: Mcclain | C6: erinmccaslun@agilityhealth.com | D6: Agility Health | E6: VP Partner Development | G6: Kurt's iPhone (personal) | H6: Kurt / Mike | I6: Connected - Need to follow-up on way ahead on IP and the NDA | J6: Connected | L6: 4 | M6: Other: Partner builder and go to market strategist | N6: Aaron was very interested in helping us use their wheel system and then helping to find ways that we can go to market and lean into each others pipelines and how we can jump on various things together | O6: Other: Do presentation to help develop our strategy to go after work together, Send Literature, Schedule Demo | P6: EMAIL_PARTNER_HIGH: Send email asking for follow-up discussion. Discussed with Mike and there might be further opportunities for us to synch up on using their wheel system and add further capabilities. Follow-up with a call and explore opportunities together. Meeting scheduled for 10/24/2024 to explore strategic plan and partnering | R6: TRUE | S6: TRUE | T6: TRUE | U6: FALSE | V6: FALSE | X6: =DATE(2024,10,15)+TIME(13,0,54) -> 45580.542 | Y6: Yes | Z6: Yes | AA6: Not Applicable | AB6: Not Applicable | AF6: completed | AG6: Business card | AH6: =DATE(2024,10,15)+TIME(19,37,10) -> 45580.817 | AK6: Large Solution | AL6: Yes
A7: Trevor | B7: Methena | C7: trevor.methena@allegion.com | D7: Allegion | E7: Release Train Engineer | F7: 5124176356 | G7: Christy's iPhone (personal) | H7: Christy | L7: 2 | M7: Influencer | N7: They are global company of IoT hardware and software. They are using agile practices and have done a lot of outsourcing overseas recently. | O7: Add to Mailing List | P7: Sent Initial Email - 23 Oct | R7: TRUE | S7: TRUE | T7: TRUE | U7: FALSE | V7: FALSE | X7: =DATE(2024,10,15)+TIME(10,39,50) -> 45580.444 | Y7: Yes | Z7: No | AG7: Scanned | AH7: =DATE(2024,10,15)+TIME(10,56,0) -> 45580.456 | AI7: Texas | AJ7: United States | AK7: Large Solution | AL7: Yes
A8: S. Hasnain | B8: Rizvi | C8: hasnain.rizvi@americannational.com | D8: American National Insurance | E8: Agile Transformation Lead | F8: 8184287768 | G8: iPad Mini (LSA/Keith) | H8: Dani | L8: 4 | M8: Decision maker | N8: Dani to schedule | O8: N/A | R8: FALSE | S8: FALSE | T8: TRUE | U8: TRUE | V8: TRUE | X8: =DATE(2024,10,15)+TIME(13,31,54) -> 45580.564 | Y8: Yes | Z8: Yes | AA8: Immediately | AG8: Scanned | AH8: =DATE(2024,10,15)+TIME(13,33,37) -> 45580.565 | AI8: Texas | AJ8: United States | AK8: Large Solution | AL8: Yes
A9: Puneeta | B9: Singh | C9: pusingh@americorps.gov | D9: AmeriCorps | E9: Project Manager | F9: 202-925-7552 | G9: iPad Mini (LSA/Keith) | H9: Christy | L9: 1 | P9: Sent Initial Email - 23 Oct | R9: TRUE | S9: TRUE | T9: TRUE | U9: FALSE | V9: FALSE | X9: =DATE(2024,10,16)+TIME(14,44,40) -> 45581.614 | Y9: No | AG9: Scanned | AH9: =DATE(2024,10,16)+TIME(14,44,46) -> 45581.614 | AI9: Virginia | AJ9: United States | AK9: Large Solution | AL9: Yes
A10: Puneeta Singh | C10: pusingh@americorps.gov | D10: Americorps | H10: Hari | L10: 1 | N10: Collected contact info after last day SAFe gov session | T10: TRUE | U10: FALSE | V10: FALSE
A11: Jamie | B11: Shopland | C11: jamie.shopland@amtrak.com | D11: Amtrak | E11: Director, Agile Transformation | F11: 3013057640 | G11: iPad Mini (LSA/Keith) | H11: Mike | L11: 4 | M11: Other: Unknown | N11: Enter to win prize. Recorded video. | O11: N/A | P11: send AFRL, R&D experience related template TEMPLATE_CLIENT_HIGH and attach LPM talkbook pdf Mention that we have experience with tranportation at California DOT, have case studies for this if interested | R11: FALSE | S11: FALSE | T11: TRUE | U11: TRUE | V11: TRUE | X11: =DATE(2024,10,15)+TIME(7,58,41) -> 45580.332 | Y11: Yes | Z11: No | AG11: Scanned | AH11: =DATE(2024,10,15)+TIME(8,0,21) -> 45580.334 | AI11: Maryland | AJ11: United States | AK11: Large Solution | AL11: Yes
A12: Thilakavathi | B12: Rajakumar | C12: thilakavathi210@gmail.com | D12: AT&T | E12: Solution Train Engineer | F12: 6782964234 | G12: iPad Tiny (LSA/Mike) | H12: Hari | L12: 1 | R12: FALSE | S12: FALSE | T12: TRUE | U12: FALSE | V12: FALSE | X12: =DATE(2024,10,16)+TIME(10,1,25) -> 45581.418 | Y12: No | AG12: Scanned | AH12: =DATE(2024,10,16)+TIME(10,14,3) -> 45581.426 | AI12: Georgia | AJ12: United States | AK12: Large Solution | AL12: Yes
A13: Bryan | B13: Smith | C13: bsmith3@atlassian.com | D13: Atlassian | E13: Jira Align Strategic Solution Sales Account Manager | F13: 720-830-6998 | G13: Christy's iPhone (personal) | H13: Christy | L13: 3 | M13: Other: jira align jira | N13: Spoke at lenght on JIRA Align and Atlassian suite | O13: Add to Mailing List | P13: Sent Initial Email - 23 Oct - connected on LinkedIn - no response to phone call left message for follow up conversation. | R13: TRUE | S13: TRUE | T13: TRUE | U13: FALSE | V13: FALSE | X13: =DATE(2024,10,14)+TIME(11,15,57) -> 45579.469 | Y13: Yes | Z13: No | AG13: Scanned | AH13: =DATE(2024,10,14)+TIME(11,16,53) -> 45579.47 | AI13: Colorado | AJ13: United States | AK13: Large Solution | AL13: Yes
A14: Mohammad Riad | B14: Hossan | C14: riad_hossan@bcbst.com | D14: BlueCross BlueShield of Tennessee, Inc | E14: Business Analyst | F14: 3098268972 | G14: iPad Mini (LSA/Keith) | H14: Hari | L14: 1 | R14: FALSE | S14: FALSE | T14: TRUE | U14: FALSE | V14: FALSE | X14: =DATE(2024,10,16)+TIME(10,28,34) -> 45581.437 | Y14: No | AG14: Scanned | AH14: =DATE(2024,10,16)+TIME(10,28,41) -> 45581.437 | AI14: Virginia | AJ14: United States | AK14: Large Solution | AL14: Yes
A15: Lisa Cohen | C15: cohen_lisa@bah.com | D15: Booz Allen Hamilton | H15: Hari | L15: 1 | N15: Collected contact info after last day SAFe gov session | T15: TRUE | U15: FALSE | V15: FALSE
A16: Jennifer Murillo | C16: murillo_jennifer@bah.com | D16: Booz Allen Hamilton | H16: Hari | L16: 1 | N16: Collected contact info after last day SAFe gov session | T16: TRUE | U16: FALSE | V16: FALSE
A17: Lynn Stevens | C17: stevens_lynn@bah.com | D17: Booz Allen Hamilton | H17: Hari | L17: 1 | N17: Collected contact info after last day SAFe gov session | T17: TRUE | U17: FALSE | V17: FALSE
A18: Paula Barbour | C18: barbour_paula@bah.com | D18: Booz Allen Hamilton | H18: Hari | L18: 1 | N18: Collected contact info after last day SAFe gov session | T18: TRUE | U18: FALSE | V18: FALSE
A19: Bonnie | B19: Soto | C19: soto_bonnie@bah.com | D19: Booz Allen Hamilton | E19: Technical Team Lead | F19: 2103241023 | G19: Taylor's iPhone (personal) | L19: 1 | R19: FALSE | S19: FALSE | T19: TRUE | U19: FALSE | V19: FALSE | X19: =DATE(2024,10,15)+TIME(13,24,0) -> 45580.558 | Y19: No | AG19: Scanned | AH19: =DATE(2024,10,15)+TIME(13,56,0) -> 45580.581 | AI19: Texas | AJ19: United States | AK19: Large Solution | AL19: Yes
A20: Jennifer Castro | C20: jennifer.castro@broadcom.com | D20: Broadcom | H20: Hari | L20: 1 | N20: Collected contact info after last day SAFe gov session | T20: TRUE | U20: FALSE | V20: FALSE
A21: Elonia | B21: Taylor | C21: elonia.taylor@bep.gov | D21: Bureau of Engraving and Printing | E21: Sr. IT Project Manager | F21: (817)528-1037 | G21: iPad Mini (LSA/Keith) | H21: Dani | L21: 5 | N21: Early in agile implementation; got SES ; want workshops and training. Lead for the program, Mike White introduced. Kurt - submitted RFI for agile coaching previously… Kurt has discussed BEP opportunities with Navy Gold Coast / Business Dev lead | R21: FALSE | S21: FALSE | T21: TRUE | U21: TRUE | V21: TRUE | X21: =DATE(2024,10,16)+TIME(13,58,44) -> 45581.582 | Y21: No | AG21: Scanned | AH21: =DATE(2024,10,16)+TIME(13,58,57) -> 45581.583 | AI21: Texas | AJ21: United States | AK21: Large Solution | AL21: Yes
A22: Steve | B22: Brylski | C22: steve.brylski@caci.com | D22: CACI | E22: Agile Transformation Leader/Coach | F22: (571) 291-7450 | G22: Mike's iPhone (personal) | H22: Mike | L22: 4 | M22: Influencer | N22: See Chris ham comments | O22: Add to Mailing List | Q22: none | R22: TRUE | S22: TRUE | T22: TRUE | U22: TRUE | V22: TRUE | X22: =DATE(2024,10,16)+TIME(13,21,24) -> 45581.557 | Y22: Yes | Z22: No | AG22: Scanned | AH22: =DATE(2024,10,17)+TIME(13,12,29) -> 45582.55 | AI22: Virginia | AJ22: United States | AK22: Large Solution | AL22: Yes
A23: Chris | B23: Ham | C23: chris.ham@caci.com | D23: CACI Inc. | E23: Agile Solution Factory Director | F23: 7036253263 | G23: Mike's iPhone (personal) | H23: Mike | L23: 4 | M23: Influencer | N23: They spoke to robin, robin mentioned LSA, they came to booth, gave them UX book, and they said they could ‘find a home’ for LSA | O23: Add to Mailing List | P23: EMAIL_PARTNER_HIGH: follow-up discussion; attach usual table insert; CC: Steve Brylski, Robin, Dani | Q23: none | R23: TRUE | S23: TRUE | T23: TRUE | U23: TRUE | V23: TRUE | X23: =DATE(2024,10,16)+TIME(13,21,29) -> 45581.557 | Y23: Yes | Z23: No | AG23: Scanned | AH23: =DATE(2024,10,17)+TIME(13,12,2) -> 45582.55 | AI23: Virginia | AJ23: United States | AK23: Large Solution | AL23: Yes
A24: Abdul Rasheed | B24: Shaik | C24: abdulrasheed.shaik@fepoc.com | D24: CareFirst | E24: Release Train Engineer | F24: 9493947591 | G24: Mike's iPhone (personal) | H24: Mike | L24: 4 | M24: Influencer | N24: Also has OPM as customer . Benefits for OPM. Was interested in various case studies and engaged | O24: Add to Mailing List | P24: EMAIL_PARTNER_MEDIUM: Send email asking for follow-up discussion; emphasize / call-out OPM case studies. Attach usual table insert | Q24: none | R24: TRUE | S24: TRUE | T24: TRUE | U24: TRUE | V24: FALSE | X24: =DATE(2024,10,15)+TIME(15,47,8) -> 45580.658 | Y24: Yes | Z24: No | AG24: Scanned | AH24: =DATE(2024,10,15)+TIME(17,38,59) -> 45580.735 | AI24: Virginia | AJ24: United States | AK24: Large Solution | AL24: Yes
A25: Hans | B25: Raj | C25: hans.raj@fepoc.com | D25: CareFirst BlueCross BlueShield (FEPOC) | E25: Lead Software Engineer/Team Coach | F25: 7038627951 | G25: iPad Mini (LSA/Mike) | H25: Larry | I25: Yes, on 11/26 | L25: 3 | M25: Influencer | N25: Gave book. Interested in AI and UX | O25: Add to Mailing List | R25: FALSE | S25: TRUE | T25: TRUE | U25: TRUE | V25: TRUE | X25: =DATE(2024,10,16)+TIME(10,21,17) -> 45581.431 | Y25: Yes | Z25: No | AG25: Scanned | AH25: =DATE(2024,10,16)+TIME(10,30,39) -> 45581.438 | AI25: Virginia | AJ25: United States | AK25: Large Solution | AL25: Yes
A26: Jalpa | B26: Purani | C26: N/A | D26: CGI | E26: Director | G26: Kurt's iPhone (personal) | H26: Kurt | I26: Connected - Discussed opportunities for SN work with CGI | J26: Connected on LinkedIn | L26: 4 | M26: Influencer | N26: She said she has a financial client that she’s working with . She is helping them with agile but really needs additional help with working with Service now. I told her I could get her connected with Craig and we can have a discussion on how we can bring all that together. | O26: Needs Technical Data, Send Literature, Add to Mailing List, Schedule Demo | P26: EMAIL_PARTNER_HIGH: Send email asking for follow-up discussion; emphasize. Setup a call to demo to discuss how we can help with SNOW. Include Craig, Mike and Kurt. 10/21: Sent email to reach out about a follow-on call. Waiting on her response and plan to follow-up Monday (10/28 if no response (KG) | R26: TRUE | S26: TRUE | T26: TRUE | U26: TRUE | V26: FALSE | X26: =DATE(2024,10,14)+TIME(15,4,39) -> 45579.628 | Y26: Yes | Z26: Yes | AA26: Within 3 months | AB26: Yes | AF26: completed | AG26: Business card | AH26: =DATE(2024,10,14)+TIME(16,49,32) -> 45579.701 | AK26: Large Solution | AL26: Yes
A27: Parag | B27: Gupta | C27: parag.gupta@cna.com | D27: CNA | E27: Director, Value Creation | F27: 4379254146 | G27: iPad Mini (LSA/Mike) | H27: Larry | I27: Yes, on 12/9 | L27: 4 | M27: Decision maker | N27: Transformation of legacy systems. Gave a book. | O27: Send Literature, Add to Mailing List | R27: FALSE | S27: TRUE | T27: TRUE | U27: TRUE | V27: TRUE | X27: =DATE(2024,10,16)+TIME(11,29,8) -> 45581.479 | Y27: Yes | Z27: No | AG27: Scanned | AH27: =DATE(2024,10,16)+TIME(11,56,20) -> 45581.497 | AJ27: Canada | AK27: Large Solution | AL27: Yes
A28: Benjamin Baghdadi | C28: bbaghdadi@cns.gov | D28: CNS | H28: Hari | L28: 1 | N28: Collected contact info after last day SAFe gov session | T28: TRUE | U28: FALSE | V28: FALSE
A29: Jacky | B29: Droushoudt | C29: jdroushoudt@pccwglobal.com | D29: Console Connect (HK) Limited | E29: AVP, Product Management (Scrum) | F29: +32494538194 | G29: Christy's iPhone (personal) | H29: Dani | L29: 4 | M29: Decision maker | N29: Was interested in what we do, wanted to stay in contact if there were stateside opprotunities. Dani and Christy both collaborated, Dani has been chatting with over LinkedIn… potentially wants a demo of the EEK presentation for his organization… Digital Transformation lead | O29: Add to Mailing List | R29: TRUE | S29: FALSE | T29: TRUE | U29: TRUE | V29: TRUE | X29: =DATE(2024,10,14)+TIME(11,1,54) -> 45579.46 | Y29: Yes | Z29: No | AG29: Scanned | AH29: =DATE(2024,10,14)+TIME(11,2,28) -> 45579.46 | AJ29: Hong Kong | AK29: Large Solution | AL29: Yes
A30: Praveen | B30: Goel | C30: praveen.goel@cprime.com | D30: cPrime | E30: SPCT, Transformation Leader, Agile Coach | F30: 2032311857 | G30: Mike's iPhone (personal) | H30: Mike | L30: 2 | M30: Other: SPCT learning about our approach | N30: hit-and-run, no real discussion | O30: Add to Mailing List | P30: EMAIL_PARTNER_LOW - nice meeting you, happy to discuss partnership opportuniites...; attach usual table insert | Q30: none | R30: TRUE | S30: TRUE | T30: TRUE | U30: FALSE | V30: FALSE | X30: =DATE(2024,10,15)+TIME(11,22,33) -> 45580.474 | Y30: Yes | Z30: No | AG30: Scanned | AH30: =DATE(2024,10,15)+TIME(11,23,24) -> 45580.475 | AI30: Connecticut | AJ30: United States | AK30: Large Solution | AL30: Yes
A31: Danny | B31: Debner | C31: danny.debner@cvent.com | D31: Cvent | G31: iPad Mini (LSA/Keith) | H31: Larry | N31: This is actually Saya Sone. I gave her a book. | R31: FALSE | S31: TRUE | T31: TRUE | U31: FALSE | V31: FALSE | X31: =DATE(2024,10,16)+TIME(15,35,32) -> 45581.65 | Y31: No | AG31: Scanned | AH31: =DATE(2024,10,16)+TIME(15,35,43) -> 45581.65 | AI31: Washington | AJ31: United States | AK31: Large Solution | AL31: Yes
A32: Richard | B32: Trice | C32: richard.w.trice.civ@health.mil | D32: DHMS/EIDS | E32: Product Manager | F32: 8304310550 | G32: iPad Mini (LSA/Keith) | H32: Christy | L32: 3 | P32: Requested LinkedIn connection - no response, called and left VM to set up meeting to reconnect | R32: TRUE | S32: TRUE | T32: TRUE | U32: FALSE | V32: FALSE | X32: =DATE(2024,10,15)+TIME(17,47,39) -> 45580.741 | Y32: No | AG32: Scanned | AH32: =DATE(2024,10,15)+TIME(17,47,51) -> 45580.742 | AI32: Texas | AJ32: United States | AK32: Large Solution | AL32: Yes
A33: Etienne | B33: LAVERDIERE | C33: elaverdiere@digitaltango.ca | D33: DIGITAL TANGO | E33: CEO | F33: +33 7 82 55 07 78 | G33: iPad Mini (LSA/Mike) | H33: Larry | I33: Yes, on 11/26 | L33: 3 | M33: Other: NA | N33: Interested in UX and design thinking | O33: Other: Gave a book to him | R33: FALSE | S33: TRUE | T33: TRUE | U33: FALSE | V33: FALSE | X33: =DATE(2024,10,15)+TIME(9,35,48) -> 45580.4 | Y33: Yes | Z33: No | AC33: 5145163100 | AG33: Scanned | AH33: =DATE(2024,10,15)+TIME(17,43,48) -> 45580.739 | AJ33: France | AK33: Large Solution | AL33: Yes
A34: Jacqueline | B34: Markot | C34: jackie.markot@discounttire.com | D34: Discount Tire | E34: Product Manager | F34: 4802627243 | G34: Taylor's iPhone (personal) | L34: 2 | M34: Influencer | N34: Looking for Ada Dash boarding and UX help. Looking for a consultant to come in and work with transparency in their organization. ￼ | O34: Other: Connect | R34: FALSE | S34: FALSE | T34: TRUE | U34: FALSE | V34: FALSE | X34: =DATE(2024,10,15)+TIME(10,48,25) -> 45580.45 | Y34: Yes | Z34: Yes | AA34: Within 3 months | AB34: Yes | AG34: Scanned | AH34: =DATE(2024,10,15)+TIME(10,58,54) -> 45580.458 | AI34: Arizona | AJ34: United States | AK34: Large Solution | AL34: Yes
A35: Blake Helander | C35: blake.helander@dodiis.mil | D35: DoD Product Manager | H35: Hari | L35: 1 | N35: Collected contact info after last day SAFe gov session | T35: TRUE | U35: FALSE | V35: FALSE
A36: Matt Lasater | C36: matt@egagedagility.com | D36: Engaged Agility | H36: Hari | L36: 1 | N36: Collected contact info after last day SAFe gov session | T36: TRUE | U36: FALSE | V36: FALSE
A37: Ken | B37: King | C37: ken.king@expleogroup.com | D37: Expleo Group | E37: Agile Coach | G37: Kurt's iPhone (personal) | H37: Dani | L37: 3 | M37: Influencer | N37: He works at Expleo Group in Dublin Ireland. He also is at Bank of America. He has a SP six, RT, SDP, LPM, PMP, ACP, RS @SP, agog Coach in Bank of America in Europe. | O37: Send Literature, Add to Mailing List | P37: EMAIL_PARTNER_HIGH: Send email asking for follow-up discussion; emphasize. As we connected, I found out that he had also met Mike Idengren at an event in Nashville.Nothing specific but may want to explore opportunites with him or/BoA further and share our work with FinTech | R37: TRUE | S37: TRUE | T37: TRUE | U37: FALSE | V37: FALSE | X37: =DATE(2024,10,14)+TIME(22,20,18) -> 45579.931 | Y37: Yes | Z37: No | AD37: Dublin | AE37: IE | AF37: completed | AG37: Business card | AH37: =DATE(2024,10,15)+TIME(2,39,18) -> 45580.111 | AK37: Large Solution | AL37: Yes
A38: Smita | B38: Saxena | C38: smita_x_saxena@fanniemae.com | D38: Fannie Mae | E38: Sr. Scrum Master | F38: 17039675748 | G38: iPad Mini (LSA/Mike) | H38: Larry | I38: Yes, on 11/26 | L38: 4 | M38: Other: Scrum master | N38: Wants to know what we do. Interest in ux | O38: Send Literature | R38: FALSE | S38: TRUE | T38: TRUE | U38: TRUE | V38: TRUE | X38: =DATE(2024,10,16)+TIME(10,12,31) -> 45581.425 | Y38: Yes | Z38: No | AG38: Scanned | AH38: =DATE(2024,10,16)+TIME(10,15,53) -> 45581.428 | AI38: Virginia | AJ38: United States | AK38: Large Solution | AL38: Yes
A39: Bethany Thomas | C39: bmthomas2@fbi.gov | D39: FBI | H39: Hari | L39: 1 | N39: Collected contact info after last day SAFe gov session | T39: TRUE | U39: FALSE | V39: FALSE
A40: Anitha | B40: Sankur | C40: anitha.sankur@atl.frb.org | D40: Federal Reserve Bank of Atlanta | E40: LEAN-Agile Coach | F40: 4232425695 | G40: iPad Mini (LSA/Mike) | H40: Hari | L40: 3 | M40: Other: Unknown | N40: Work with Mike - find out who got the SAFe ARCH training | O40: Add to Mailing List | R40: FALSE | S40: FALSE | T40: TRUE | U40: FALSE | V40: FALSE | X40: =DATE(2024,10,16)+TIME(12,3,2) -> 45581.502 | Y40: Yes | Z40: No | AG40: Scanned | AH40: =DATE(2024,10,16)+TIME(13,42,33) -> 45581.571 | AI40: Georgia | AJ40: United States | AK40: Large Solution | AL40: Yes
...

Sheet Post-conf leads (Round 1)
A1: First Name | B1: Last Name | C1: Email Address | D1: Company Name | E1: Title | F1: Mobile Phone Number | G1: Device used to scan badge | H1: Contact Owner | I1: Role of this person | J1: DURING-Summit notes | K1: Lead Score | L1: DURING-summit follow-up notes | M1: POST-Summit Follow-up Notes | N1: POST-Summit Follow-up Jira tickets | O1: POST-Summit lead qual & follow-up planning done | P1: POST-Summit follow-ups done (week of Oct 21-25) | Q1: Created date/time US/Eastern | R1: Qualified | S1: Is the person currently evaluating solutions related to [specific problem/industry]? | T1: What is the timeframe for choosing a solution? | U1: Is there a budget for this business need? | V1: Work Phone Number | W1: Work City | X1: Work State | Y1: Lead Transcription Status | Z1: Lead Source | AA1: Last Update US/Eastern | AB1: What State do you reside in: | AC1: Country you reside in: | AD1: Sponsorship Level | AE1: Event Sponsor
A2: Dave | B2: Turner | C2: david.p.turner.civ@us.navy.mil | D2: NAVAIR | E2: Release Manager | G2: Kurt's iPhone (personal) /Taylor's iPhone (personal) | H2: Kurt | I2: Influencer | J2: Replacing Kimberly Wade. Know each other for a long time. Needs help with tooling. Retired 26 year marine who retired in 2013.. At China Lake. From Canton Ohio. (KG) | K2: 5 | L2: Needs Technical Data, Send Literature, Add to Mailing List, Schedule Demo | M2: Do not contact at this time, work through chain of command, starting with Kim. Hot near-term demand / follow-up interest indicated, could lead to opportunities <60 days. Kimberly / Dave will ask for a follow-up meeting on week of Oct 21. NOTE: Mike already sent promised case study (automated quads) over LinkedIn Mike and Dani had call today (10/23) with Kimberly and Dave to reengage on moving this forward (KG) | N2: none | O2: TRUE | P2: TRUE | Q2: =DATE(2024,10,15)+TIME(16,31,50) -> 45580.689 | R2: Yes | S2: Yes | T2: Within 3 months | U2: Not Applicable | Y2: completed | Z2: Business card | AA2: =DATE(2024,10,15)+TIME(17,19,30) -> 45580.722 | AD2: Large Solution | AE2: Yes
A3: Gerd | B3: Wessling | C3: gerd.wessling@scagilize.de | D3: Scagilize GmbH | E3: Founder & Managing Director | F3: +491704445773 | G3: Christy's iPhone (personal) / Kurt's Iphone (personal) | H3: Christy | I3: Budget authority | J3: Wants to do LinkedIn posts with content. Owner of the company. Interested in expanding his operations globally. He wanted our slides from Eek Monsters presentation and was to tag us in a linked in post | K3: 5 | L3: Other: Send slides Wants to expand globally with his agile operations. Based in Germany | M3: EMAIL_PARTNER_HIGH: Send email asking for follow-up discussion. Dani sent Gerd our slides and Gerd included us in a LinkedIn post. Seemed very interested in what we do and is interested in expanding his operations gloally. Let's connect on how we can get inserted into the expansion plan. - is going to do the outreach. Dani sent the EEK slides to him and he is looking to expand his operations globally using LSA as a partner (KG)- Sent Email and have meeting set for Thursday morning for initial touch point- good initial meeting - Gerd will reach out to set up meeting in next few weeks to follow up and continue establishing networking opporotunities. ( https://www.scagilize.de/en-gb) | O3: TRUE | P3: TRUE | Q3: =DATE(2024,10,14)+TIME(11,4,21) -> 45579.461 | R3: Yes | S3: Yes | Z3: Scanned | AA3: =DATE(2024,10,14)+TIME(11,5,43) -> 45579.462 | AC3: Germany | AD3: Large Solution | AE3: Yes
A4: Elonia | B4: Taylor | C4: elonia.taylor@bep.gov | D4: Bureau of Engraving and Printing | E4: Sr. IT Project Manager | F4: (817)528-1037 | G4: iPad Mini (LSA/Keith) | H4: Dani | J4: Early in agile implementation; got SES ; want workshops and training. Lead for the program, Mike White introduced. Kurt - submitted RFI for agile coaching previously… Kurt has discussed BEP opportunities with Navy Gold Coast / Business Dev lead | K4: 5 | O4: FALSE | P4: FALSE | Q4: =DATE(2024,10,16)+TIME(13,58,44) -> 45581.582 | R4: No | Z4: Scanned | AA4: =DATE(2024,10,16)+TIME(13,58,57) -> 45581.583 | AB4: Texas | AC4: United States | AD4: Large Solution | AE4: Yes
A5: Lesa | B5: Kennedy | C5: lesa_kennedy@glic.com | D5: Guardian Life Insurance | E5: Enterprise Methodology Coach | F5: 3474329075 | G5: iPad Mini (LSA/Keith) | H5: Dani | I5: Influencer | J5: Send follow up on Business Teams needing support for agile implementation. | K5: 5 | L5: Send Literature, Add to Mailing List | O5: FALSE | P5: FALSE | Q5: =DATE(2024,10,15)+TIME(8,6,27) -> 45580.338 | R5: Yes | S5: Yes | T5: Immediately | U5: Yes | Z5: Scanned | AA5: =DATE(2024,10,15)+TIME(8,8,31) -> 45580.339 | AB5: New York | AC5: United States | AD5: Large Solution | AE5: Yes
A6: Cori | B6: Creran | C6: cori.creran@nationalgrid.com | D6: National Grid | E6: Manager, Portfolio Planning | F6: 603-801-2139 | G6: Mike's iPhone (personal) | H6: Mike | J6: See William Leach | K6: 5 | M6: cc on William email | N6: see william | O6: TRUE | P6: TRUE | Q6: =DATE(2024,10,17)+TIME(14,28,3) -> 45582.603 | R6: No | Z6: Scanned | AA6: =DATE(2024,10,17)+TIME(14,28,9) -> 45582.603 | AB6: New Hampshire | AC6: United States | AD6: Large Solution | AE6: Yes
A7: William | B7: Leach | C7: william.leach@nationalgrid.com | D7: National Grid | E7: Director | F7: 4806202483 | G7: Mike's iPhone (personal) | H7: Mike | J7: Met during LPM workshop day. Discussed their lean portfolio re-organization approach on the flipchart, and listened to their pain points around getting data from Alfabet. Discussed that an effective EA should help summarize key data for LPM dev/maintenance activities, and William sent me an email asking for an example of a model-based portfolio canvas | K7: 5 | M7: EMAIL_CLIENT_CUSTOM - Develop demo assets in ARIS. Make the messaging easy to consume, e.g., 2page talkbook, follow-up with email and call(s) to get a meeting for next steps. Cc: Cori, Dani, Christy | N7: https://leanscaledarchitects.atlassian.net/browse/PIPE-396 | O7: TRUE | P7: TRUE | Q7: =DATE(2024,10,17)+TIME(14,27,51) -> 45582.603 | R7: No | Z7: Scanned | AA7: =DATE(2024,10,17)+TIME(14,27,58) -> 45582.603 | AB7: New York | AC7: United States | AD7: Large Solution | AE7: Yes
A8: Lindsey | B8: Benson | C8: lindsey.a.benson2.civ@us.navy.mil | D8: NAVAIR | E8: RTE | F8: 760-793-8291 | G8: iPad Mini (LSA/Keith) | H8: Mike | K8: 5 | M8: Do not contact at this time , work through chain of command, starting with Kim | N8: none | O8: TRUE | P8: TRUE | Q8: =DATE(2024,10,16)+TIME(10,14,55) -> 45581.427 | R8: No | Z8: Scanned | AA8: =DATE(2024,10,16)+TIME(10,15,0) -> 45581.427 | AB8: California | AC8: United States | AD8: Large Solution | AE8: Yes
A9: Samuel | B9: Celestine | C9: samuel.r.celestine.civ@us.navy.mil | D9: NAVAIR | E9: RTE | F9: RTE | G9: iPad Mini (LSA/Keith) | H9: Mike | K9: 5 | M9: Do not contact at this time , work through chain of command, starting with Kim | N9: none | O9: TRUE | P9: TRUE | Q9: =DATE(2024,10,16)+TIME(10,14,48) -> 45581.427 | R9: No | Z9: Scanned | AA9: =DATE(2024,10,16)+TIME(10,14,54) -> 45581.427 | AB9: California | AC9: United States | AD9: Large Solution | AE9: Yes
A10: Joshua | B10: Derouse | C10: joshua.m.derousse.civ@us.navy.mil | D10: NAVAIR | E10: Mission System PM | F10: Mission System PM | G10: iPad Mini (LSA/Keith) | H10: Mike | K10: 5 | M10: Do not contact at this time , work through chain of command, starting with Kim | N10: none | O10: TRUE | P10: TRUE | Q10: =DATE(2024,10,16)+TIME(10,15,0) -> 45581.427 | R10: No | Z10: Scanned | AA10: =DATE(2024,10,16)+TIME(10,15,5) -> 45581.427 | AB10: California | AC10: United States | AD10: Large Solution | AE10: Yes
A11: Suzette | B11: Johnson | C11: suzette.johnson@ngc.com | D11: Northrop Grumman | E11: NG Fellow | F11: 410-746-7987 | G11: iPad Mini (LSA/Mike) | H11: Taylor | I11: Influencer | J11: Taylor - work with Dani to discuss this need with Suzette | K11: 5 | L11: Add to Mailing List | M11: Reading between the lines, they need some process modeling/intelligence work too | O11: FALSE | P11: FALSE | Q11: =DATE(2024,10,15)+TIME(11,14,41) -> 45580.469 | R11: Yes | S11: No | Z11: Scanned | AA11: =DATE(2024,10,15)+TIME(17,43,48) -> 45580.739 | AB11: Maryland | AC11: United States | AD11: Large Solution | AE11: Yes
A12: Parag | B12: Gupta | C12: parag.gupta@cna.com | D12: CNA | E12: Director, Value Creation | F12: 4379254146 | G12: iPad Mini (LSA/Mike) | H12: Larry | I12: Decision maker | J12: Transformation of legacy systems. Gave a book. | K12: 4 | L12: Send Literature, Add to Mailing List | O12: FALSE | P12: TRUE | Q12: =DATE(2024,10,16)+TIME(11,29,8) -> 45581.479 | R12: Yes | S12: No | Z12: Scanned | AA12: =DATE(2024,10,16)+TIME(11,56,20) -> 45581.497 | AC12: Canada | AD12: Large Solution | AE12: Yes
A13: Paul | B13: Gattis | C13: Bad email address. Sent a LinkedIn Connection | D13: AFSC/SWTP | G13: Kurt's iPhone (personal) | H13: Kurt | I13: Influencer | J13: He is a engineer for a software development department that they stood up. He’s looking to see about the various enterprise architecture and understanding how they’re spending on their IT investments. Also looking at helping to understand more about how they can potentially get the organization to more standardize around the actual way of doing business.￼ | K13: 4 | L13: Needs Technical Data, Send Literature, Add to Mailing List | M13: EMAIL_PARTNER_HIGH: Send email asking for follow-up discussion. Setup a follow-on conversation to help him assess a possible path forward and help the organization with stremlining their SDLC operations and bringing standardized approach to AFSC. 10/21: Sent a LinkedIn Connection since his email address bounced. Waiting on a reply but will follow-up on 10/28 if no response. | O13: TRUE | P13: FALSE | Q13: =DATE(2024,10,15)+TIME(11,49,59) -> 45580.493 | R13: Yes | S13: Yes | T13: Not Applicable | U13: Not Applicable | Y13: transcription incomplete | Z13: Business card | AA13: =DATE(2024,10,15)+TIME(12,19,45) -> 45580.514 | AD13: Large Solution | AE13: Yes
A14: Bhavani | B14: Krishnan | C14: bhavani.krishnan@agilevelocity.com | D14: Agile Velocity | E14: Enterprise Agile Coach | F14: 571.246.0602 | G14: iPad Mini (LSA/Keith) / Kurt's iPhone (personal) | H14: Kurt | I14: Budget authority | J14: Looking for partnership opportunity. Spoke to Kurt. They are in the commercial space and interact with cyber security. They are very interested in looking at their women owned an 8a. Spoke with her and their chief revenue officer James Hawks. | K14: 4 | L14: Other: X | M14: EMAIL_PARTNER_HIGH: Send email asking for follow-up discussion. Setup further discussion on how we can partner and help one another by leveraging their 8a. Meeting scheduled for 10/24/2024 to explore strategic plan and partnering with her and James Hawks | O14: TRUE | P14: TRUE | Q14: =DATE(2024,10,15)+TIME(10,49,18) -> 45580.451 | R14: Yes | Z14: Scanned | AA14: =DATE(2024,10,15)+TIME(11,2,31) -> 45580.46 | AB14: Virginia | AC14: United States | AD14: Large Solution | AE14: Yes
A15: S. Hasnain | B15: Rizvi | C15: hasnain.rizvi@americannational.com | D15: American National Insurance | E15: Agile Transformation Lead | F15: 8184287768 | G15: iPad Mini (LSA/Keith) | H15: Dani | I15: Decision maker | J15: Dani to schedule | K15: 4 | L15: N/A | O15: FALSE | P15: FALSE | Q15: =DATE(2024,10,15)+TIME(13,31,54) -> 45580.564 | R15: Yes | S15: Yes | T15: Immediately | Z15: Scanned | AA15: =DATE(2024,10,15)+TIME(13,33,37) -> 45580.565 | AB15: Texas | AC15: United States | AD15: Large Solution | AE15: Yes
A16: Steve | B16: Brylski | C16: steve.brylski@caci.com | D16: CACI | E16: Agile Transformation Leader/Coach | F16: (571) 291-7450 | G16: Mike's iPhone (personal) | H16: Mike | I16: Influencer | J16: See Chris ham comments | K16: 4 | L16: Add to Mailing List | N16: none | O16: TRUE | P16: TRUE | Q16: =DATE(2024,10,16)+TIME(13,21,24) -> 45581.557 | R16: Yes | S16: No | Z16: Scanned | AA16: =DATE(2024,10,17)+TIME(13,12,29) -> 45582.55 | AB16: Virginia | AC16: United States | AD16: Large Solution | AE16: Yes
A17: Chris | B17: Ham | C17: chris.ham@caci.com | D17: CACI Inc. | E17: Agile Solution Factory Director | F17: 7036253263 | G17: Mike's iPhone (personal) | H17: Mike | I17: Influencer | J17: They spoke to robin, robin mentioned LSA, they came to booth, gave them UX book, and they said they could ‘find a home’ for LSA | K17: 4 | L17: Add to Mailing List | M17: EMAIL_PARTNER_HIGH: follow-up discussion; attach usual table insert; CC: Steve Brylski, Robin, Dani | N17: none | O17: TRUE | P17: TRUE | Q17: =DATE(2024,10,16)+TIME(13,21,29) -> 45581.557 | R17: Yes | S17: No | Z17: Scanned | AA17: =DATE(2024,10,17)+TIME(13,12,2) -> 45582.55 | AB17: Virginia | AC17: United States | AD17: Large Solution | AE17: Yes
A18: Abdul Rasheed | B18: Shaik | C18: abdulrasheed.shaik@fepoc.com | D18: CareFirst | E18: Release Train Engineer | F18: 9493947591 | G18: Mike's iPhone (personal) | H18: Mike | I18: Influencer | J18: Also has OPM as customer . Benefits for OPM. Was interested in various case studies and engaged | K18: 4 | L18: Add to Mailing List | M18: EMAIL_PARTNER_MEDIUM: Send email asking for follow-up discussion; emphasize / call-out OPM case studies. Attach usual table insert | N18: none | O18: TRUE | P18: TRUE | Q18: =DATE(2024,10,15)+TIME(15,47,8) -> 45580.658 | R18: Yes | S18: No | Z18: Scanned | AA18: =DATE(2024,10,15)+TIME(17,38,59) -> 45580.735 | AB18: Virginia | AC18: United States | AD18: Large Solution | AE18: Yes
A19: Erin | B19: Mcclain | C19: erinmccaslun@agilityhealth.com | D19: Agility Health | E19: VP Partner Development | G19: Kurt's iPhone (personal) | H19: Kurt | I19: Other: Partner builder and go to market strategist | J19: Aaron was very interested in helping us use their wheel system and then helping to find ways that we can go to market and lean into each others pipelines and how we can jump on various things together | K19: 4 | L19: Other: Do presentation to help develop our strategy to go after work together, Send Literature, Schedule Demo | M19: EMAIL_PARTNER_HIGH: Send email asking for follow-up discussion. Discussed with Mike and there might be further opportunities for us to synch up on using their wheel system and add further capabilities. Follow-up with a call and explore opportunities together. Meeting scheduled for 10/24/2024 to explore strategic plan and partnering | O19: TRUE | P19: TRUE | Q19: =DATE(2024,10,15)+TIME(13,0,54) -> 45580.542 | R19: Yes | S19: Yes | T19: Not Applicable | U19: Not Applicable | Y19: completed | Z19: Business card | AA19: =DATE(2024,10,15)+TIME(19,37,10) -> 45580.817 | AD19: Large Solution | AE19: Yes
A20: Jacky | B20: Droushoudt | C20: jdroushoudt@pccwglobal.com | D20: Console Connect (HK) Limited | E20: AVP, Product Management (Scrum) | F20: +32494538194 | G20: Christy's iPhone (personal) | H20: Dani | I20: Decision maker | J20: Was interested in what we do, wanted to stay in contact if there were stateside opprotunities. Dani and Christy both collaborated, Dani has been chatting with over LinkedIn… potentially wants a demo of the EEK presentation for his organization… Digital Transformation lead | K20: 4 | L20: Add to Mailing List | O20: TRUE | P20: FALSE | Q20: =DATE(2024,10,14)+TIME(11,1,54) -> 45579.46 | R20: Yes | S20: No | Z20: Scanned | AA20: =DATE(2024,10,14)+TIME(11,2,28) -> 45579.46 | AC20: Hong Kong | AD20: Large Solution | AE20: Yes
A21: Brenda | B21: Dixon | C21: bspatt04@gmail.com | D21: Kapitus | E21: Scrum Master | F21: 5712135904 | G21: Taylor's iPhone (personal) | H21: Taylor | I21: Influencer | J21: Small business lending firm. Excited about the agile/EA combined approach. Excited about assessments | K21: 4 | L21: Send Literature, Add to Mailing List, Other: Contact | M21: sending case studies and reaching out to explore pain points | O21: FALSE | P21: FALSE | Q21: =DATE(2024,10,15)+TIME(11,38,2) -> 45580.485 | R21: Yes | S21: Yes | T21: Immediately | U21: Yes | Z21: Scanned | AA21: =DATE(2024,10,15)+TIME(11,47,58) -> 45580.492 | AB21: Virginia | AC21: United States | AD21: Large Solution | AE21: Yes
A22: Alan | B22: Hammond | C22: alan.hammond@chase.com | D22: JPMorgan Chase | E22: VP Technology | F22: 6146200281 | G22: Mike's iPhone (personal) | H22: Mike | I22: Decision maker | J22: Quick discussion , follow up if possible on Digital Formula , need to learn more about pain points | K22: 4 | L22: Add to Mailing List | M22: EMAIL_CLIENT_HIGH - Send email asking for follow-up discussion; recapd discussion, especially pain points discussed; attach usual table insert | O22: TRUE | P22: TRUE | Q22: =DATE(2024,10,15)+TIME(10,31,11) -> 45580.438 | R22: Yes | S22: No | Z22: Scanned | AA22: =DATE(2024,10,15)+TIME(11,6,41) -> 45580.463 | AB22: Ohio | AC22: United States | AD22: Large Solution | AE22: Yes
A23: Jessica | B23: Crocker | C23: jessica_crocker@navyfederal.org | D23: Navy Federal Credit Union | E23: Scrum Master | F23: 5716091755 | G23: Taylor's iPhone (personal) | H23: Taylor | I23: Influencer | J23: Likes the EA/Agile approach. Send case studies on GRC, modeling, quads, agile | K23: 4 | L23: Send Literature, Add to Mailing List, Other: Contact | M23: They want to read/talk more about our case studies, specifically Process-Aligned Risk and Compliance Automation, Automated Quads, Agile Assessment and Improvement, Alfabet ITPM (Federated Bank), and Effective Agility. | O23: FALSE | P23: FALSE | Q23: =DATE(2024,10,17)+TIME(11,57,39) -> 45582.498 | R23: No | Z23: Scanned | AA23: =DATE(2024,10,17)+TIME(11,57,43) -> 45582.498 | AB23: Maryland | AC23: United States | AD23: Large Solution | AE23: Yes
A24: Joseph | B24: Marina | C24: jmarina@lmi.org | D24: LMI | E24: Fellow, Agile Coach | F24: 2107731114 | G24: iPad Mini (LSA/Keith) | H24: Larry | I24: Influencer | J24: Gave a book | K24: 4 | L24: Other: UX quantification needs , add to linkedin | O24: FALSE | P24: TRUE | Q24: =DATE(2024,10,15)+TIME(10,14,53) -> 45580.427 | R24: Yes | S24: Yes | T24: Not Applicable | U24: Not Applicable | Z24: Scanned | AA24: =DATE(2024,10,15)+TIME(11,22,24) -> 45580.474 | AB24: Texas | AC24: United States | AD24: Large Solution | AE24: Yes
A25: Denise | B25: Amling | C25: denise.t.amling@nasa.gov | D25: NASA | E25: Agile Coach | F25: 9493105907 | G25: iPad Mini (LSA/Keith) | H25: Keith | I25: Influencer | J25: Took the app rat assessment. Working on beginning stages of a new app inventory system at nasa. Curious if alfabet is fedramp. Follow up with her. | K25: 4 | L25: Add to Mailing List, Schedule Demo | M25: Keith sent email to Denise. | N25: Do I need one? | O25: TRUE | P25: TRUE | Q25: =DATE(2024,10,15)+TIME(11,59,16) -> 45580.499 | R25: Yes | S25: Yes | T25: Not Applicable | U25: Not Applicable | Z25: Scanned | AA25: =DATE(2024,10,15)+TIME(12,15,10) -> 45580.511 | AB25: Virginia | AC25: United States | AD25: Large Solution | AE25: Yes
A26: Pierrette | B26: Njikang | C26: pierrette_njikang@navyfederal.org | D26: Navy Federal Credit Union | E26: Scrum Master | F26: 5716511147 | G26: Taylor's iPhone (personal) | H26: Taylor | I26: Influencer | J26: Likes the EA/Agile approach. Send case studies on GRC, modeling, quads, agile | K26: 4 | L26: Send Literature, Add to Mailing List, Other: Contact | M26: They want to read/talk more about our case studies, specifically Process-Aligned Risk and Compliance Automation, Automated Quads, Agile Assessment and Improvement, Alfabet ITPM (Federated Bank), and Effective Agility. | O26: FALSE | P26: FALSE | Q26: =DATE(2024,10,15)+TIME(10,17,21) -> 45580.429 | R26: Yes | S26: No | Z26: Scanned | AA26: =DATE(2024,10,17)+TIME(11,27,23) -> 45582.477 | AB26: Virginia | AC26: United States | AD26: Large Solution | AE26: Yes
A27: Jalpa | B27: Purani | D27: CGI | E27: Director | G27: Kurt's iPhone (personal) | H27: Kurt | I27: Influencer | J27: She said she has a financial client that she’s working with . She is helping them with agile but really needs additional help with working with Service now. I told her I could get her connected with Craig and we can have a discussion on how we can bring all that together. | K27: 4 | L27: Needs Technical Data, Send Literature, Add to Mailing List, Schedule Demo | M27: EMAIL_PARTNER_HIGH: Send email asking for follow-up discussion; emphasize. Setup a call to demo to discuss how we can help with SNOW. Include Craig, Mike and Kurt. 10/21: Sent email to reach out about a follow-on call. Waiting on her response and plan to follow-up Monday (10/28 if no response (KG) | O27: TRUE | P27: TRUE | Q27: =DATE(2024,10,14)+TIME(15,4,39) -> 45579.628 | R27: Yes | S27: Yes | T27: Within 3 months | U27: Yes | Y27: completed | Z27: Business card | AA27: =DATE(2024,10,14)+TIME(16,49,32) -> 45579.701 | AD27: Large Solution | AE27: Yes
A28: Janeen | B28: Osselborn | C28: janeen.osselborn@servicenow.com | D28: ServiceNow | E28: Advisory Solution Consultant | G28: Kurt's iPhone (personal) | H28: Kurt | I28: Influencer | J28: The service now Team stopped by. They wanted to look at their EA told that they just released and use in SPM portfolio management element of it along with service now. Very interested in what we have to offer. They said they’ll stop back by later. | K28: 4 | L28: Needs Technical Data, Send Literature, Add to Mailing List, Current Customer, Schedule Demo | M28: EMAIL_PARTNER_HIGH: Send email asking for follow-up discussion. See Fred Champlain. Sent email to reach out about a follow-on call. Waiting on her response and plan to follow-up Monday (10/28 if no response (KG) | O28: TRUE | P28: TRUE | Q28: =DATE(2024,10,15)+TIME(15,44,8) -> 45580.656 | R28: Yes | S28: Yes | T28: Within 3 months | U28: Yes | Y28: completed | Z28: Business card | AA28: =DATE(2024,10,15)+TIME(17,20,50) -> 45580.723 | AD28: Large Solution | AE28: Yes
A29: Eva | B29: Owusu | C29: eva_owusu@navyfederal.org | D29: Navy Federal Credit Union | E29: Lead System Analyst | F29: 5715850177 | G29: Taylor's iPhone (personal) | H29: Taylor | I29: Influencer | J29: Likes the EA/Agile approach. Send case studies on GRC, modeling, quads, agile | K29: 4 | L29: Send Literature, Add to Mailing List, Other: Contact | M29: They want to read/talk more about our case studies, specifically Process-Aligned Risk and Compliance Automation, Automated Quads, Agile Assessment and Improvement, Alfabet ITPM (Federated Bank), and Effective Agility. | O29: FALSE | P29: FALSE | Q29: =DATE(2024,10,15)+TIME(10,17,35) -> 45580.429 | R29: No | Z29: Scanned | AA29: =DATE(2024,10,15)+TIME(10,17,46) -> 45580.429 | AB29: Virginia | AC29: United States | AD29: Large Solution | AE29: Yes
A30: Marco | B30: Guerrero | C30: Dani | D30: TecVeris | E30: Director, Tooling Solutions | F30: 5128297440 | G30: Taylor's iPhone (personal) | H30: Taylor | I30: Decision maker | J30: Looking for federal partners. Taylor and Kurt saw the demo of their nVeris tool that can use AI to quickly layout the business process for agencies quickly and then you can have real time interaction online with others in the org to make sure the process is fully captured | K30: 4 | M30: Reaching out to establish a partering relationship | O30: FALSE | P30: FALSE | Q30: =DATE(2024,10,14)+TIME(17,33,59) -> 45579.732 | R30: Yes | S30: Yes | Z30: Scanned | AA30: =DATE(2024,10,14)+TIME(17,34,40) -> 45579.732 | AB30: Texas | AC30: United States | AD30: Large Solution | AE30: Yes
A31: Millie | B31: Paniccia | C31: millie.paniccia@tecveris.com | D31: TecVeris | E31: Co-Founder & Managing Partner | F31: 4438037180 | G31: Taylor's iPhone (personal) | H31: Taylor | I31: Budget authority | J31: Looking for federal partners | K31: 4 | M31: Reaching out to establish a partering relationship | O31: FALSE | P31: FALSE | Q31: =DATE(2024,10,14)+TIME(17,34,46) -> 45579.732 | R31: Yes | S31: Yes | T31: Immediately | U31: Yes | V31: 4438037180 | Z31: Scanned | AA31: =DATE(2024,10,15)+TIME(11,1,39) -> 45580.459 | AB31: Maryland | AC31: United States | AD31: Large Solution | AE31: Yes
A32: Alyssa | B32: Catalano | C32: alyssa.catalano@panasonic.aero | D32: Panasonic Avionics | E32: Director -Project Management | F32: 949-690-8070 | G32: Mike's iPhone (personal) | H32: Mike | I32: Influencer | J32: Met at lunch on LPM workshop day. Panasonic , developing entertainment systems for aircraft , got a few ARTs, leadership not getting agile , competing “frameworks”, software dev using it … advised on improving principle 7 & showing success in key areas, and making it less about frameworks and more about outcomes and results .. | K32: 4 | L32: Add to Mailing List | M32: EMAIL_CLIENT_CUSTOM - Send the same LPM 2-page talkbook (National Grid) to Alyssa and see if that helps spark discussion around Panasonic pain points ; insert usual links table | N32: https://leanscaledarchitects.atlassian.net/browse/PIPE-396 | O32: TRUE | P32: TRUE | Q32: =DATE(2024,10,17)+TIME(13,1,48) -> 45582.543 | R32: Yes | S32: No | Z32: Scanned | AA32: =DATE(2024,10,17)+TIME(13,10,43) -> 45582.549 | AB32: California | AC32: United States | AD32: Large Solution | AE32: Yes
A33: Angela | B33: Campbell | C33: angela.campbell@progress.com | D33: Progress Software | E33: Senior Director of Transformation | F33: 6035828980 | G33: iPad Tiny (LSA/Mike) | H33: Hari | I33: Influencer | K33: 4 | L33: Needs Technical Data, Add to Mailing List | M33: Progress Software Corporation is an American public company that produces software for creating and deploying business applications. Founded in Burlington, Massachusetts with offices in 16 countries, the company posted revenues of $531.3 million in 2021 and employs approximately 2100 people. Send general TEMPLATE_CUSTOMER_HIGH (4/5 template) with LPM talkbook pdf Send draft to Mike/Dani for feedback | O33: FALSE | P33: FALSE | Q33: =DATE(2024,10,16)+TIME(10,8,5) -> 45581.422 | R33: Yes | S33: Yes | T33: Not Applicable | U33: Not Applicable | Z33: Scanned | AA33: =DATE(2024,10,16)+TIME(10,14,3) -> 45581.426 | AB33: Massachusetts | AC33: United States | AD33: Large Solution | AE33: Yes
A34: Fred | B34: Champlain | C34: frederic.champlain@servicenow.com | D34: Service Now | E34: Agile Evangelist SPM BU | G34: Kurt's iPhone (personal) / Mike's iPhone (personal) | H34: Craig | I34: Influencer | J34: The service now Team stopped by. They wanted to look at their EA tool that they just released and use in our portfolio management element of it along with service now. Very interested in what we have to offer. They said they’ll stop back by later (KG) Works with With dan wood at snow … connect with both about EA (MI) | K34: 4 | L34: Schedule Demo Needs Technical Data, Send Literature, Add to Mailing List, Current Customer, Schedule Demo | M34: EMAIL_PARTNER_HIGH: Send email asking for follow-up discussion. Schedule a demo and have Craig do a demo on how we can show EA capabilities. Include Mike, Craig, Kurt | O34: TRUE | P34: TRUE | Q34: =DATE(2024,10,15)+TIME(15,43,56) -> 45580.656 | R34: Yes | S34: Yes | T34: Within 3 months | U34: Not Applicable | Y34: completed | Z34: Business card | AA34: =DATE(2024,10,15)+TIME(16,48,59) -> 45580.701 | AD34: Large Solution | AE34: Yes
A35: Srinivasa | B35: Kasturi | C35: skasturi@worldbank.org | D35: The World Bank Group | E35: Senior Information Security Officer | F35: 5714369070 | G35: iPad Mini (LSA/Keith) | H35: Larry | I35: Decision maker | J35: Interested in what secure UX is. Larry talked with him a bit. Gave him copy of book. Curious on how to do the UX research; liked the templates in the book. Question asked about ‘how do we get the developer to think about how a system can be abused/hacked during the design.’ Done through task flow analysis. Help them understand why they are doing it. | K35: 4 | L35: Needs Technical Data, Schedule Demo | O35: FALSE | P35: TRUE | Q35: =DATE(2024,10,15)+TIME(11,33,33) -> 45580.482 | R35: Yes | S35: No | Z35: Scanned | AA35: =DATE(2024,10,15)+TIME(11,39,32) -> 45580.486 | AB35: Virginia | AC35: United States | AD35: Large Solution | AE35: Yes
A36: Amber | B36: O Grady | D36: US Air Force | G36: Kurt's iPhone (personal) | H36: Kurt | I36: Influencer | J36: Amber and 3 other team members stopped by the booth. The work at Wright-Patterson in the Financial Management Division. They would be good to follow-up with. Mike mentioned the work we have done with Navy FMP and they seemed interested to learn more. | K36: 4 | M36: Some interest and discussion about pain points and/or LSA solution. Setup a call to follow-up on their needs in finance at WPAFB and uncover more ways we can possibly engage. Sent email to reach out about a follow-on call. Waiting on her response and plan to follow-up Monday (10/28 if no response (KG) | O36: TRUE | P36: TRUE | Q36: =DATE(2024,10,15)+TIME(13,0,30) -> 45580.542 | R36: No | Y36: completed | Z36: Business card | AA36: =DATE(2024,10,15)+TIME(19,37,54) -> 45580.818 | AD36: Large Solution | AE36: Yes
A37: Timothy | B37: Worley | C37: tworley@twilio.com | D37: Twilio | E37: Principal Technical Program Manager | F37: 2106870800 | G37: iPad Tiny (LSA/Mike) | H37: Hari | I37: Influencer | J37: Very interested in learning more about our service details to help improve twilio scaled agile adoption | K37: 4 | L37: Send Literature, Add to Mailing List, Schedule Demo | M37: Talk to Dani about pain points relevant for this lead - template for those who want scaled agile implementation and LSA's services | O37: FALSE | P37: FALSE | Q37: =DATE(2024,10,15)+TIME(15,37,14) -> 45580.651 | R37: Yes | S37: No | Z37: Scanned | AA37: =DATE(2024,10,15)+TIME(17,46,25) -> 45580.741 | AB37: Texas | AC37: United States | AD37: Large Solution | AE37: Yes
A38: Jorge | B38: Garcia | C38: jorge.garcia1@usaa.com | D38: USAA | E38: Program Manager Lead/RTE | F38: 210-771-4845 | G38: Mike's iPhone (personal) | H38: Mike | I38: Influencer | J38: Discussed our involvement with ARIS GRC effort at USAA; they recognized the value and said it is still in use. They were in a hurry. Need more discussion to discover pain points / sell vectors | K38: 4 | L38: Add to Mailing List | M38: EMAIL_CLIENT_CUSTOM - Send the same LPM 2-page talkbook (National Grid) ; recap our discussion about ARIS and other tools can help integrate business / IT EA data to help with ompliance, better solution designs and summarized into a Lean Portfolio Canvas. cc: Bonnie Cortez | O38: TRUE | P38: TRUE | Q38: =DATE(2024,10,15)+TIME(15,20,37) -> 45580.639 | R38: Yes | S38: No | Z38: Scanned | AA38: =DATE(2024,10,15)+TIME(17,42,53) -> 45580.738 | AB38: Texas | AC38: United States | AD38: Large Solution | AE38: Yes
A39: Smita | B39: Saxena | C39: smita_x_saxena@fanniemae.com | D39: Fannie Mae | E39: Sr. Scrum Master | F39: 17039675748 | G39: iPad Mini (LSA/Mike) | H39: Larry | I39: Other: Scrum master | J39: Wants to know what we do. Interest in ux | K39: 4 | L39: Send Literature | O39: FALSE | P39: TRUE | Q39: =DATE(2024,10,16)+TIME(10,12,31) -> 45581.425 | R39: Yes | S39: No | Z39: Scanned | AA39: =DATE(2024,10,16)+TIME(10,15,53) -> 45581.428 | AB39: Virginia | AC39: United States | AD39: Large Solution | AE39: Yes
A40: James | B40: Hogan | C40: jimmy.hogan@gmail.com | D40: Samtec | E40: Director of R&D | F40: 8033512796 | G40: iPad Mini (LSA/Mike) | H40: Hari | I40: Influencer | J40: Casual interest. Keep in email list. | K40: 4 | L40: Send Literature | M40: send AFRL, R&D experience related template TEMPLATE_CLIENT_HIGH and attach LPM talkbook pdf | O40: FALSE | P40: FALSE | Q40: =DATE(2024,10,16)+TIME(10,17,26) -> 45581.429 | R40: Yes | S40: No | Z40: Scanned | AA40: =DATE(2024,10,16)+TIME(10,19,0) -> 45581.43 | AB40: South Carolina | AC40: United States | AD40: Large Solution | AE40: Yes
...

Sheet Registrant -Attendee Burndown 
A1: Company Name | B1: Title | C1: Name | D1: Scaled Agile Partner | E1: Summit Sponsor? | F1: Met Before? | G1: In Hubspot | H1: LSA Assigned POC | I1: Status on OutReach - Kurt email | J1: Status on OutReach - app | K1: Intro text | L1: Notes
A2: 76 SWEG/ 558 CL | B2: Director | G2: No
A3: 76 SWEG/ 558 MXDPA | B3: Product Manager | G3: No
A4: 76 SWEG/ 558 MXDPB | B4: Computer Scientist/Product Manager | G4: No
A5: 76 SWEG/ 558 MXDPC | B5: Lead Acquisition Program Manager | G5: No
A6: 76th Software Engineering Group (76 SWEG) | B6: Industrial Engineer | G6: No
A7: Acato Information Management, LLC | B7: CEO | G7: No
A8: Accenture Federal Services | B8: SAFe SPCT | D8: Global SPCT | G8: Yes | H8: Kurt | I8: Email Sent | J8: Sent | K8: Hello Shawn. I wanted to follow up on my previous email regarding potential opportunities to connect at the SAFe Summit. LSA Digital specializes in agility-at-scale + EA + ITSM solutions, and we’re keen to explore ways to collaborate or partner with Accenture to enhance process maturity and compliance adoption. Looking forward to hearing from you and hopefully discussing potential synergies at the Summit! | L8: Chris Palmisano David Sanvar Erica Stevens Nicole Koonce Mr Scott Frost Shelagh Worfolk STEVE "ACE" LEE
A9: Accenture Federal Services (AFS) | B9: SAFe Fellow SPCT | D9: Global SPCT | G9: No | H9: Kurt | I9: Email Sent | J9: Sent | K9: Hello Shawn. I wanted to follow up on my previous email regarding potential opportunities to connect at the SAFe Summit. LSA Digital specializes in agility-at-scale + EA + ITSM solutions, and we’re keen to explore ways to collaborate or partner with Accenture to enhance process maturity and compliance adoption. Looking forward to hearing from you and hopefully discussing potential synergies at the Summit! | L9: Shawn Lowe
A10: Adaptavist | B10: VP Enterprise Agility | D10: Gold | E10: Yes | G10: No | H10: Kurt | I10: Email Sent | J10: Sent | K10: Hello Jean. I wanted to follow up on my previous email regarding potential opportunities to connect at the SAFe Summit. LSA Digital specializes in agility-at-scale + EA + ITSM solutions, and we’re eager to explore ways to collaborate or partner with Adaptavist to enhance process maturity and compliance adoption. Looking forward to hearing from you and hopefully discussing potential synergies at the Summit! | L10: Cassandra Moll Jean Henson Lorenzo aluzzi Peter Kerigan Tina Behers Vanessa Finnie
A11: Adaptworks | B11: Chief Learning Officer | D11: Gold | G11: No | H11: Kurt | I11: Email Sent | J11: Connected / Sent | K11: Hello Roberto. I wanted to follow up on my previous email regarding potential opportunities to connect at the SAFe Summit. LSA Digital specializes in agility-at-scale + EA + ITSM solutions, and we’re eager to explore ways to collaborate or partner with Adaptworks to enhance process maturity and compliance adoption. Looking forward to hearing from you and hopefully discussing potential synergies at the Summit! | L11: Roberto Baptista, PhD
A12: Advance Agility | B12: SAFe Coach - SPCT | D12: Platinum SPCT | G12: No | H12: Dani
A13: Aedifides LLC | B13: Founder | G13: No
A14: AFSC/SWTP | B14: Electronics Engineer | G14: No
A15: Agile Agilist | B15: VP Transformation | G15: No | H15: Dani
A16: Agile Big Picture | B16: Consultant, SPCT, SAFe Fellow | G16: No | H16: Dani
A17: Agile Hive | B17: Sales Consultant | D17: Platform | E17: Yes | G17: No | H17: Dani | J17: Sent | K17: I wanted to freach out about potential opportunities to connect at the SAFe Summit. LSA Digital, like Agile Hive, is an Atlassian partner specializing in agility-at-scale + EA + ITSM solutions, and we see great potential for collaboration. We’d love to explore how our Agile transformation and enterprise architecture capabilities can complement your offerings to drive even greater value for clients. | L17: Daniel Roller Janik Röhler Joshua Brock Mr. Thomas Kretzer Veline Schroth
A18: Agile Rising | B18: CEO, SPCT | D18: Gold SPCT | G18: No | H18: Dani | J18: Sent | K18: I’m reaching out regarding potential opportunities to connect at the SAFe Summit. LSA Digital specializes in agility-at-scale + EA + ITSM solutions, and we see strong potential for collaboration with Agile Rising, given your expertise in enterprise agility and SAFe transformation. We’d love to explore how our Agile transformation and enterprise architecture capabilities can complement your offerings to drive greater value for clients. | L18: Chrstopher Ruch
A19: Agile Velocity | B19: Transformation Coach | D19: Silver | G19: No | H19: Dani | J19: Sent | K19: I’m reaching out regarding potential opportunities to connect at the SAFe Summit. LSA Digital specializes in agility-at-scale + EA + ITSM solutions, and we see strong potential for collaboration with Agile Velocity, given your expertise in Agile transformation and scaling frameworks. We’d love to explore how our Agile transformation and enterprise architecture capabilities can complement your services to drive greater value for clients. | L19: Bhavani Krishnan Dave Gipp David Pointer James Hawks
A20: AgileKlix | B20: Agile Coach | G20: No | H20: Dani
A21: AgileMindset | B21: Managing Director | G21: No | H21: Dani
A22: AgileSherpas | B22: Chief Value Officer | D22: Bronze | F22: Yes | G22: No | H22: Dani | J22: Sent | K22: I’m reaching out regarding potential opportunities to connect at the SAFe Summit. LSA Digital specializes in agility-at-scale + EA + ITSM solutions, and we see strong potential for collaboration with AgileSherpas, given your expertise in Agile marketing and transformation. We’d love to explore how our Agile transformation and enterprise architecture capabilities can complement your services to drive greater value for clients. | L22: Andrea Fyrear Ross Libby
A23: AgilityHealth | B23: VP Partners and Government | D23: Platform | E23: Yes | F23: Georgia Ouren - This is an opportunity for LSA to partner with Agility Health Radar and Scaled Agile Institute to provide training as part of gap closure from the health assessments service. | G23: Yes | H23: Dani | I23: Email Sent | J23: Connected / Sent | K23: I’m reaching out regarding potential opportunities to connect at the SAFe Summit. LSA Digital specializes in agility-at-scale + EA + ITSM solutions, and we see great potential for collaboration with AgilityHealth, given your expertise in Agile maturity assessments and transformation. We’d love to explore how our Agile transformation and enterprise architecture capabilities can complement your offerings to drive greater value for clients. | L23: Erin Rae McCaslin Georgia Ouren Mike Stoner Trisha Hal
A24: AgilityIRL, Inc. | B24: Partner | G24: No | H24: Dani
A25: Aledade | B25: Director, Agile Process | G25: No
A26: Allegion | B26: Release Train Engineer | G26: No
